Workbook

Sheet README
A1: AccuSync - Delivery Roadmap
A3: What this workbook is
A4: A tracking view of the AccuSync delivery plan. Every requirement in DOC-076814 Rev 01 has been mapped to a feature, and every feature to an epic and a milestone. Use the Epics and Features sheets to record progress: the Impact and State columns are dropdowns.
A6: The four sheets
A7: README | B7: This sheet. What the workbook is, the headline numbers, and what each column means.
A8: Milestone | B8: The eight milestones, their target dates, and what has to be true for each to be done.
A9: Epics | B9: 25 epics in delivery order. What workflow each covers, its impact, state, milestone and notes.
A10: Features | B10: Features grouped under their epic, each with the exact requirement IDs it satisfies.
A12: Headline numbers
A13: Requirements in DOC-076814 Rev 01 | C13: 196
A14: Milestones | C14: 8
A15: Epics | C15: 25
A16: Features | C16: 67
A18: How the work is structured
A19: EPIC (a section of the requirement document) -> FEATURE (one useful capability) -> USER STORY (one piece of work, one pull request).
A20: Tables and repositories are built inside the epic that needs them, not up front. The shared Add/Edit/Delete and Save/Revert/Undo framework is built once inside Patient Management and then adopted by each later epic.
A22: Column meanings
A23: Workflow | B23: What the user actually does, end to end, that this epic or feature covers.
A24: Requirement IDs | B24: The exact GID numbers from DOC-076814 that it satisfies. "Enabler" means it supports the product without satisfying a requirement of its own.
A25: Impact | B25: High = blocks other work, or core clinical function, or compliance. Medium = required, not blocking. Low = small, deferred, or waiting on an external answer.
A26: State | B26: Yet to start / In progress / Complete. Dropdown.
A27: Milestone | B27: Which milestone this lands in. See the Milestone sheet.
A28: Target date | B28: The milestone date.
A29: Builds tables | B29: Yes means this feature creates database tables. Tables are built inside the epic that needs them.

Sheet Milestone
A1: Milestones
A3: Milestone | B3: Name | C3: Total hours | D3: Total days | E3: Exit criterion - it is done when
A4: M1 | B4: Solid ground / Patient records exist / The patient list is usable | C4: =SUMIFS('Task Breakdown'!$J:$J,'Task Breakdown'!$N:$N,$A4) | D4: =C4/8 | E4: Builds from a fresh copy, login, logging, a patient can be created, viewed, edited and soft-deleted and survives a restart, with the list, search and test list working
A5: M2 | B5: Patient configuration / Risk factors and comments | C5: =SUMIFS('Task Breakdown'!$J:$J,'Task Breakdown'!$N:$N,$A5) | D5: =C5/8 | E5: An administrator can set mandatory and active fields, the patient ID format, list sorting, confirmation prompts and validation rules. Risk factors and comments are administrator-managed lists with translations, assignable to a patient. Patient report prints. Patient Management complete
A6: M3 | B6: Test results | C6: =SUMIFS('Task Breakdown'!$J:$J,'Task Breakdown'!$N:$N,$A6) | D6: =C6/8 | E6: TEOAE, DPOAE and ABR results viewable with waveforms, demonstrated on real screening data loaded through the parsers that already work
A7: M4 | B7: Administration | C7: =SUMIFS('Task Breakdown'!$J:$J,'Task Breakdown'!$N:$N,$A7) | D7: =C7/8 | E7: Users with working account creation and password rules, profiles with real permissions, devices, sites, facilities, locations, both protocol types
A8: M5 | B8: Data in and out | C8: =SUMIFS('Task Breakdown'!$J:$J,'Task Breakdown'!$N:$N,$A8) | D8: =C8/8 | E8: All five import formats parse and save. All available export formats write to the right folders with the right file names
A9: M6 | B9: Reports and language | C9: =SUMIFS('Task Breakdown'!$J:$J,'Task Breakdown'!$N:$N,$A9) | D9: =C9/8 | E9: Patient reports print and export. The application runs in the agreed languages
A10: M7 | B10: Integration | C10: =SUMIFS('Task Breakdown'!$J:$J,'Task Breakdown'!$N:$N,$A10) | D10: =C10/8 | E10: S4H sync works against a test endpoint. Device connects over USB both ways. Firmware updates
A11: M8 | B11: Finish and ship | C11: =SUMIFS('Task Breakdown'!$J:$J,'Task Breakdown'!$N:$N,$A11) | D11: =C11/8 | E11: Help available in the application, audit trail and logging in place, databases encrypted and verified, installer proven on clean Windows 11 Pro and Enterprise, and every one of the 196 requirements is either built and tested or formally out of scope
B12: TOTAL | C12: =SUM(C4:C11) | D12: =SUM(D4:D11)

Sheet Epics
A1: # | B1: Epic | C1: Jira | D1: Epic name | E1: Workflow this epic covers | F1: Requirement IDs | G1: Impact | H1: State | I1: Milestone | J1: Total hours | K1: Total days | L1: Notes
A2: 1 | B2: Epic 0 | C2: ASWD-77 | D2: Revamp Code Base | E2: Developer and build workflow, plus the shared plumbing every later epic uses. Get a clean copy of the repository to build, then create the base classes, navigation services and the two databases that all other epics depend on. | F2: Enabler - no requirement | G2: High | H2: In progress | I2: M1 | J2: =SUMIFS('Task Breakdown'!$J:$J,'Task Breakdown'!$L:$L,$C2) | K2: =J2/8 | L2: Nothing else can be trusted until this lands. The solution currently fails to build from a fresh copy, and the three migrations run in the wrong order so a brand-new database cannot be created.
A3: 2 | B3: Epic 1 | C3: ASWD-1 | D3: Login | E3: Sign in, sign out, and being locked out. A user enters a username and password, is refused if the account is deactivated or locked, and is locked after five failed attempts for an administrator-configurable period. | F3: GID-255015-255019, GID-255021 | G3: Medium | H3: In progress | I3: M1 | J3: =SUMIFS('Task Breakdown'!$J:$J,'Task Breakdown'!$L:$L,$C3) | K3: =J3/8 | L3: Six of the eight requirements are already built and covered by 103 passing tests. Only closure and re-verification remain, because none of it is on main yet. The other two requirements moved to ASWD-7.
A4: 3 | B4: Epic 26 | C4: ASWD-26 | D4: Logging: the basics | E4: Diagnosing problems after the fact. AccuSync writes informational, warning and error messages to a file with timestamps, keeps patient-identifiable data out of them, and carries logging into the code already written. Rotation and retention are ASWD-31. | F4: GID-255031-255034, GID-255038 | G4: Medium | H4: Yet to start | I4: M1 | J4: =SUMIFS('Task Breakdown'!$J:$J,'Task Breakdown'!$L:$L,$C4) | K4: =J4/8 | L4: this epic is the logging basics only - a working logger, the agreed format, the patient-data rule, and logging added to the Epic 0 and Epic 1 code. It sits at position 4 so every later epic is written with logging available rather than having it retrofitted. Rotation, retention and file protection moved to ASWD-31 late in the plan, because they produce nothing a stakeholder can see.
A5: 4 | B5: Epic 2 | C5: ASWD-2 | D5: Patient Management | E5: The whole clinical record workflow. A screener creates a baby's record, fills in demographics, caregiver and medical details, answers the risk-factor questions, adds comments, finds the baby again in the list, reviews the tests recorded against it, and prints a report. An administrator configures which fields appear, which are mandatory, how the list sorts, and what the risk-factor and comment lists contain. | F5: GID-254873-254893, GID-254895-254897, GID-254950-254964, GID-254966, GID-255009, GID-255012, GID-255466 | G5: High | H5: Yet to start | I5: M1-M2 | J5: =SUMIFS('Task Breakdown'!$J:$J,'Task Breakdown'!$L:$L,$C5) | K5: =J5/8 | L5: The largest epic at 136 days, about a fifth of the project. Delivered in four slices (2A to 2D) so there are four checkpoints instead of one 36-week run. Absorbs the old ASWD-15, ASWD-16 and ASWD-17. Nothing in this area is persisted today.
A6: 5 | B6: Epic 5 | C6: ASWD-5 | D6: OAE Test Result | E6: Reviewing an otoacoustic emission result. A user opens a completed TEOAE or DPOAE test and sees the result detail, the waveform, the test comments and which device recorded it. | F6: GID-254901-254902 | G6: Medium | H6: Yet to start | I6: M3 | J6: =SUMIFS('Task Breakdown'!$J:$J,'Task Breakdown'!$L:$L,$C6) | K6: =J6/8 | L6: Moved ahead of Import and Export by decision D15, because waveforms on screen are the most visible thing in the product. Starts with a two-day investigation, because neither the waveform storage format nor a way to draw it exists yet. F5 is essential: it loads a real device file through the three parsers that already work, so the views are demonstrated on genuine screening data rather than invented data.
A7: 6 | B7: Epic 6 | C7: ASWD-6 | D7: ABR Test Result | E7: Reviewing an auditory brainstem response result. A user opens a completed ABR test and sees the result detail, the waveform, EEG noise and impedance readings, comments and device information. | F7: GID-254903 | G7: Medium | H7: Yet to start | I7: M3 | J7: =SUMIFS('Task Breakdown'!$J:$J,'Task Breakdown'!$L:$L,$C7) | K7: =J7/8 | L7: Cheaper than ASWD-5 because the waveform investigation and drawing code are reused. TestRecord already carries the ABR-specific fields.
A8: 7 | B8: Epic 7 | C8: ASWD-7 | D8: User Account Management | E8: Managing who can use AccuSync. An administrator creates a user, sets their profile and display language, activates or deactivates them, unlocks a locked account, and sets the password rules and lockout duration that apply to everyone. | F8: GID-254904-254912, GID-255020, GID-255022 | G8: High | H8: Yet to start | I8: M4 | J8: =SUMIFS('Task Breakdown'!$J:$J,'Task Breakdown'!$L:$L,$C8) | K8: =J8/8 | L8: F1 matters more than it looks: there is currently no working way to create a real user account, which is why the password-history rule in GID-255020 can never fire. Absorbs four items moved from ASWD-1.
A9: 8 | B9: Epic 8 | C9: ASWD-8 | D9: Profile Management | E9: Deciding what each kind of user is allowed to do. An administrator creates a profile, ticks the individual permissions it grants, and assigns it to users. Those permissions then control which screens and actions each person sees. | F9: GID-254913-254918 | G9: High | H9: Yet to start | I9: M4 | J9: =SUMIFS('Task Breakdown'!$J:$J,'Task Breakdown'!$L:$L,$C9) | K9: =J9/8 | L9: Replaces three hardcoded role presets in C# with real database-driven profiles. Warning: the 33 permission fields are recorded only in a .sql file due to be deleted, so Epic 0 F4 must capture them first.
A10: 9 | B10: Epic 9 | C10: ASWD-9 | D10: Device Management | E10: Keeping track of the screening devices a site owns. An administrator adds a device, records its name and serial number, assigns which users and which facilities it belongs to, configures its on-device settings, and sees when it was last seen and what firmware it is running. | F10: GID-254919-254926 | G10: Medium | H10: Yet to start | I10: M4 | J10: =SUMIFS('Task Breakdown'!$J:$J,'Task Breakdown'!$L:$L,$C10) | K10: =J10/8 | L10: Do not start F4 until question Q8 is answered. GID-254925 is a safety-related requirement pointing at Hazard 6.4, and the risk assessment document has not been provided.
A11: 10 | B11: Epic 10 | C11: ASWD-10 | D11: Site Management | E11: Setting up the organisation, top level. An administrator records each site with its name, description and code, and decides whether the site and facility list is pushed out to devices. | F11: GID-254927-254931, GID-255001-255002 | G11: Medium | H11: Yet to start | I11: M4 | J11: =SUMIFS('Task Breakdown'!$J:$J,'Task Breakdown'!$L:$L,$C11) | K11: =J11/8 | L11: Also builds the shared 'can this record be deleted?' check that Facility, Location, Profile, Device, Protocol, Risk Factor and Comment all reuse.
A12: 11 | B12: Epic 11 | C12: ASWD-11 | D12: Facility Management | E12: Setting up the organisation, middle level. An administrator records each facility with its name, description, code, parent site and location type. | F12: GID-254932-254936 | G12: Medium | H12: Yet to start | I12: M4 | J12: =SUMIFS('Task Breakdown'!$J:$J,'Task Breakdown'!$L:$L,$C12) | K12: =J12/8 | L12: Reuses the in-use check built in ASWD-10. Needed by ASWD-9 F3, which assigns facilities to devices.
A13: 12 | B13: Epic 12 | C13: ASWD-12 | D13: Location Management | E13: Setting up the organisation, lowest level. An administrator records each location and can assign a new location to every facility at once. | F13: GID-254937-254941, GID-255465 | G13: Medium | H13: Yet to start | I13: M4 | J13: =SUMIFS('Task Breakdown'!$J:$J,'Task Breakdown'!$L:$L,$C13) | K13: =J13/8
A14: 13 | B14: Epic 13 | C14: ASWD-13 | D14: ABR Test Protocol Configuration | E14: Defining how an ABR test is run. An administrator creates a named test protocol, sets its parameters, and edits or deletes protocols later. | F14: GID-254942-254945 | G14: Medium | H14: Yet to start | I14: M4 | J14: =SUMIFS('Task Breakdown'!$J:$J,'Task Breakdown'!$L:$L,$C14) | K14: =J14/8 | L14: The allowed values for each protocol parameter exist only in a .sql file due to be deleted. Epic 0 F4 must capture them first or this epic loses its specification.
A15: 14 | B15: Epic 14 | C15: ASWD-14 | D15: DPOAE Test Protocol Configuration | E15: Defining how a DPOAE test is run. Same workflow as the ABR protocol epic, for the other test type. | F15: GID-254946-254949 | G15: Medium | H15: Yet to start | I15: M4 | J15: =SUMIFS('Task Breakdown'!$J:$J,'Task Breakdown'!$L:$L,$C15) | K15: =J15/8 | L15: Same warning as ASWD-13 about the parameter value ranges.
A16: 15 | B16: Epic 3 | C16: ASWD-32 | D16: Data Exchange: import, export and S4H | E16: Moving data in and out of AccuSync, in every format, both ways. A user imports a file a screening device or another system produced, and exports patients and results back out in the format the receiving system needs, with the exact folder and file name the requirements specify and patient identifiers stripped if asked. AccuSync also signs on to the national SMaRT4Hearing service, receives the authoritative lists of users, devices, facilities and risk factors, and sends screening results back. | F16: GID-254898-254900, GID-254971-254995, GID-256274-256286, GID-256512 | G16: High | H16: Yet to start | I16: M5-M7 | J16: =SUMIFS('Task Breakdown'!$J:$J,'Task Breakdown'!$L:$L,$C16) | K16: =J16/8 | L16: Replaces ASWD-3 Import, ASWD-4 Export and ASWD-20 S4H, merged per D20: one feature per format, import and export finished together. Reading the AccuLink source removed the 3-day SEDQ discovery and unblocked the HiTrack and OZ file layouts - the contract is northgate.wsdl and the layouts are declared in HiTrackTest and Oz7Test. CSV is the one format AccuLink cannot answer, so Q3 still blocks F3. Needs a Jira epic number.
A17: 16 | B17: Epic 18 | C17: ASWD-18 | D17: Report Generation | E17: Producing something to hand over or file. A user picks a patient, chooses a report, and AccuSync renders it with the hospital logo and the chosen paper size, then prints it or saves it to a file. | F17: GID-254894, GID-254965, GID-255112-255113 | G17: Medium | H17: Yet to start | I17: M6 | J17: =SUMIFS('Task Breakdown'!$J:$J,'Task Breakdown'!$L:$L,$C17) | K17: =J17/8 | L17: Starts with an investigation, because there is no reporting library in the solution at all. Question Q5 may fold ASWD-2 F9 into this epic.
A18: 17 | B18: Epic 19 | C18: ASWD-19 | D18: Language | E18: Using AccuSync in another language. A user or administrator picks a language, confirms the change, and every piece of on-screen text, message and result appears in it. | F18: GID-254967-254970, GID-256513 | G18: Medium | H18: Yet to start | I18: M6 | J18: =SUMIFS('Task Breakdown'!$J:$J,'Task Breakdown'!$L:$L,$C18) | K18: =J18/8 | L18: 1,204 strings are already externalised, but they are duplicated across two projects and there are zero translation files. Scope depends entirely on question Q1. Translation itself is not a development task and is not in the estimate.
A19: 18 | B19: Epic 21 | C19: ASWD-21 | D19: Device Communication (+ Firmware) | E19: Talking to the AccuScreen Pro. A user plugs a device in over USB, AccuSync shows it connecting, reads its identity and firmware version, sends patients and configuration down to it, pulls completed test results back, and updates its firmware with warnings and progress shown. | F19: GID-254996-255005, GID-255010-255011, GID-255044-255045 | G19: High | H19: Yet to start | I19: M7 | J19: =SUMIFS('Task Breakdown'!$J:$J,'Task Breakdown'!$L:$L,$C19) | K19: =J19/8 | L19: The project that should hold all of this does not exist on disk. Blocked on question Q10: no protocol specification, no confirmed physical device, and the requirements say USB while the architecture document says serial port. Its investigation is pulled forward.
A20: 19 | B20: Epic 24 | C20: ASWD-24 | D20: Alarms, Warnings, Operator Messages | E20: Telling the user what is happening. Progress is shown during slow operations such as printing, data transfer and firmware updates, and the user is warned before an inactivity logout. | F20: GID-255008-255014 | G20: Medium | H20: Yet to start | I20: M8 | J20: =SUMIFS('Task Breakdown'!$J:$J,'Task Breakdown'!$L:$L,$C20) | K20: =J20/8 | L20: Five of its seven requirements are delivered by other epics. F2 is blocked: GID-255014 asks for a warning before automatic logout, but no requirement describes the logout itself (question Q13).
A21: 20 | B21: Epic 31 | C21: ASWD-31 | D21: Logging: retention and protection | E21: Keeping the log files under control. Log files roll daily and at 5 MB, are named to a set pattern, are kept 366 days then deleted oldest-first, cannot be read by an ordinary user, and cannot be deleted or modified through anything AccuSync provides. | F21: GID-255035-255037 | G21: Low | H21: Yet to start | I21: M8 | J21: =SUMIFS('Task Breakdown'!$J:$J,'Task Breakdown'!$L:$L,$C21) | K21: =J21/8 | L21: Split out of ASWD-26 and placed here on purpose: none of it is visible to a stakeholder, and the logger it protects already exists from Epic 26. Sits next to Audit Trail because that needs the same rolling, retention and protection approach. NEEDS A JIRA EPIC - ASWD-31 is a placeholder. GID-255037 was reworded by Natus but is not yet changed in Jama.
A22: 21 | B22: Epic 25 | C22: ASWD-25 | D22: Audit Trail | E22: Proving who did what. Every login, patient change, configuration change, synchronisation and firmware update is written to an audit log with the user, time, description, device and outcome, and kept for at least a year. | F22: GID-255023-255030 | G22: High | H22: Yet to start | I22: M8 | J22: =SUMIFS('Task Breakdown'!$J:$J,'Task Breakdown'!$L:$L,$C22) | K22: =J22/8 | L22: Deliberately late, per decision D6. One consequence: patient records created during testing before this lands will have no audit history. Also, with two databases an audit entry and the change it records cannot be written in one transaction, so it is best-effort.
A23: 22 | B23: Epic 27 | C23: ASWD-27 | D23: About | E23: Finding out what you are running. A user opens About and sees the version number, the manufacturer name and the website. | F23: GID-255039 | G23: Low | H23: Yet to start | I23: M8 | J23: =SUMIFS('Task Breakdown'!$J:$J,'Task Breakdown'!$L:$L,$C23) | K23: =J23/8
A24: 23 | B24: Epic 28 | C24: ASWD-28 | D24: Help | E24: Getting help without leaving the application. A user opens the help documentation from inside AccuSync, or presses the Help icon on a screen and lands on the page for that screen. | F24: GID-255040-255041 | G24: Low | H24: Yet to start | I24: M8 | J24: =SUMIFS('Task Breakdown'!$J:$J,'Task Breakdown'!$L:$L,$C24) | K24: =J24/8 | L24: Building the viewer is development work. Writing the help content is not, and no help content exists (question Q15).
A25: 24 | B25: Epic 30 | C25: ASWD-30 | D25: Installation | E25: Getting AccuSync onto a machine and off it again, encrypted and on a supported system. A guided installer checks prerequisites and the operating system, installs the application, switches on database encryption and verifies it, and the uninstaller removes everything with a choice to keep or delete the database. | F25: GID-255006-255007, GID-255042-255047, GID-256510-256511 | G25: High | H25: Yet to start | I25: M8 | J25: =SUMIFS('Task Breakdown'!$J:$J,'Task Breakdown'!$L:$L,$C25) | K25: =J25/8 | L25: Absorbs ASWD-22 (network check), ASWD-23 (Windows 11 check) and ASWD-29 (database storage and encryption) per decision D14, growing from 15.0 to 27.0 days and 10 requirements. Built at delivery time per D9, so only a fresh install has to be proven. F6 must include a full regression pass: everything up to this point is developed against unencrypted databases, and an encrypted SQLite provider changes the connection string and can change file-locking and performance behaviour.
A26: 25 | B26: Epic 33 | C26: ASWD-33 | D26: Release: release testing and documentation | E26: Taking a feature-complete build and shipping it. Every one of the 196 requirements is tested by hand against a named build with the evidence recorded, defects are triaged and re-tested, the product is installed and proven on a clean machine of each supported Windows version, and it ships with a user manual, instructions for use and release notes. | F26: Enabler - no requirement | G26: High | H26: Yet to start | I26: M8 | J26: =SUMIFS('Task Breakdown'!$J:$J,'Task Breakdown'!$L:$L,$C26) | K26: =J26/8 | L26: Added at the code reviewer's request, then scoped to two features by the lead the same day: release testing and user documentation. The integration suite, requirement traceability, the IEC 62304 records and the ISO 14971 risk file were cut and risk R3 is reopened for them - on a medical device they are mandatory, so the likely owner is Natus's own quality and regulatory function. No SRS requirement covers release, testing or documentation, which is why this work was invisible.
I27: TOTAL | J27: =SUM(J2:J26) | K27: =SUM(K2:K26)

Sheet Features
A1: # | B1: Epic | C1: Jira | D1: Epic name | E1: Slice | F1: Feature | G1: Feature name | H1: Workflow this feature covers | I1: Requirement IDs | J1: Builds tables | K1: Impact | L1: State | M1: Milestone | N1: Total hours | O1: Total days | P1: Notes
A2: 1 | B2: Epic 0 | C2: ASWD-77 | D2: Revamp Code Base | F2: F1 | G2: Architecture revamp | H2: Fix the clean-copy build failure --> architecture revamp | I2: Enabler - no requirement | J2: Yes | K2: High | L2: In progress | M2: M1 | N2: =SUMIFS('Task Breakdown'!$J:$J,'Task Breakdown'!$L:$L,$C2,'Task Breakdown'!$M:$M,$F2) | O2: =N2/8
A3: 2 | B3: Epic 1 | C3: ASWD-1 | D3: Login | F3: F1 | G3: Login and Logout of AccuSync | H3: The user can log in, log out, and change the password. | I3: GID-255015, GID-255016, GID-255017, GID-255018, GID-255019, GID-255021 | K3: Medium | L3: In progress | M3: M1 | N3: =SUMIFS('Task Breakdown'!$J:$J,'Task Breakdown'!$L:$L,$C3,'Task Breakdown'!$M:$M,$F3) | O3: =N3/8
A4: 3 | B4: Epic 26 | C4: ASWD-26 | D4: Logging: the basics | F4: F1 | G4: Logging that works, and logging in the code already written | H4: Logging interface in `Core`, file output, four levels (Debug / Info / Warning / Error), the agreed entry format, written to `%ProgramData%\Natus\AccuSync\Logs`, with exception logging that records type and message but never `ex.ToString()` -> Convert the existing `Debug.WriteLine` and `Console.WriteLine` calls -> Add logging to the Epic 0 and Epic 1 code already written | I4: GID-255031, GID-255032, GID-255033, GID-255034, GID-255038 | K4: High | L4: Yet to start | M4: M1 | N4: =SUMIFS('Task Breakdown'!$J:$J,'Task Breakdown'!$L:$L,$C4,'Task Breakdown'!$M:$M,$F4) | O4: =N4/8
A5: 4 | B5: Epic 2 | C5: ASWD-2 | D5: Patient Management | E5: 2A | F5: F1 | G5: Create, view, edit and delete a patient record | H5: Create the `Patients` and `PatientContacts` tables, repository and service -> Add a new patient -> View a patient -> Edit a patient -> Soft-delete a patient -> The 19 ALGO device fields the ALGO 5 / ALGO Pro devices send that AccuSync cannot store, plus the Physician / Pediatrician relabel that fixes a live import defect, and Medication becomes multi-line. Scope confirmed by Natus— the baby’s own address and phone were dropped -> The AccuLink fields AccuSync is missing — 22 fields plus Birth Location becoming a combo box, from two places and both of them AccuLink: its own field set (six confirmed, the rest from the alignment the lead is running with Natus) and its HiTrack and Australia data-exchange plugins (seven fields, fully enumerated). Combo boxes rather than plain dropdowns, typed values saved on the patient only, one shared Race list — all three confirmed by Natus. The comparison and the Natus sign-off are not development work and are not costed · | I5: GID-254883, GID-254885, GID-254886, GID-254891 | J5: Yes | K5: High | L5: Yet to start | M5: M1 | N5: =SUMIFS('Task Breakdown'!$J:$J,'Task Breakdown'!$L:$L,$C5,'Task Breakdown'!$M:$M,$F5) | O5: =N5/8
A6: 5 | B6: Epic 2 | C6: ASWD-2 | D6: Patient Management | E6: 2A | F6: F2 | G6: Shared Add/Edit/Delete and Save/Revert/Undo framework | H6: Shared Add/Edit/Delete commands and the delete-confirmation prompt -> Shared change-tracking and undo stack for Save/Revert/Undo -> Warn before closing or navigating away with unsaved changes | I6: GID-254873, GID-254874, GID-254875, GID-254876, GID-254877, GID-254878, GID-254879, GID-254880, GID-254881, GID-254882, GID-255009 | K6: High | L6: Yet to start | M6: M1 | N6: =SUMIFS('Task Breakdown'!$J:$J,'Task Breakdown'!$L:$L,$C6,'Task Breakdown'!$M:$M,$F6) | O6: =N6/8 | P6: First build of the shared framework, per decision D11. Later epics adopt it.
A7: 6 | B7: Epic 2 | C7: ASWD-2 | D7: Patient Management | E7: 2B | F7: F3 | G7: Show and search the patient list | H7: Show the patient list with the 6 required columns -> Build-your-own filter across several fields at once — Phase 1 per Natus, needs a new requirement -> Search by patient ID, first name, last name, date of birth, or test date range | I7: GID-254884, GID-254887, GID-254890 | K7: High | L7: Yet to start | M7: M1 | N7: =SUMIFS('Task Breakdown'!$J:$J,'Task Breakdown'!$L:$L,$C7,'Task Breakdown'!$M:$M,$F7) | O7: =N7/8
A8: 7 | B8: Epic 2 | C8: ASWD-2 | D8: Patient Management | E8: 2B | F8: F4 | G8: Show, delete and reassign test results, with permissions enforced | H8: Create the `TestSessions` and `TestRecords` tables -> Show the test list with the 7 required columns -> Delete one test entry, admin only -> Move a test result to the correct patient -> Enforce "unless locked by permissions" on edit -> Limit test delete and test reassignment to administrators. Patient delete is open to every user, by customer decision | I8: GID-254895, GID-254896, GID-254897 | J8: Yes | K8: High | L8: Yet to start | M8: M1 | N8: =SUMIFS('Task Breakdown'!$J:$J,'Task Breakdown'!$L:$L,$C8,'Task Breakdown'!$M:$M,$F8) | O8: =N8/8
A9: 8 | B9: Epic 2 | C9: ASWD-2 | D9: Patient Management | E9: 2B | F9: F5 | G9: Store the field setup, validate input and enforce mandatory fields | H9: Create the `FieldSetup` and `SystemSettings` tables -> Show which fields are mandatory -> Only allow save when mandatory fields are filled -> Validate input and block saving bad data -> Show which field is wrong and what to fix | I9: GID-254892, GID-254893, GID-254966, GID-255012 | J9: Yes | K9: High | L9: Yet to start | M9: M1 | N9: =SUMIFS('Task Breakdown'!$J:$J,'Task Breakdown'!$L:$L,$C9,'Task Breakdown'!$M:$M,$F9) | O9: =N9/8
A10: 9 | B10: Epic 2 | C10: ASWD-2 | D10: Patient Management | E10: 2C | F10: F6 | G10: Configure patient fields, ID format, list sorting and prompts | H10: Choose which patient fields are mandatory and which are shown -> Configure the patient ID format check -> Configure how the patient list is sorted -> Turn on or off: confirm on save, confirm on delete, warn on change -> Rename patient field labels — all 62 fields, not only the 4 spare "Available Field" slots -> Patient QR code, and the "include in QR" choice per field — Phase 1 per Natus, needs a new requirement | I10: GID-254960, GID-254961, GID-254962, GID-254963, GID-254964, GID-255466 | K10: Medium | L10: Yet to start | M10: M2 | N10: =SUMIFS('Task Breakdown'!$J:$J,'Task Breakdown'!$L:$L,$C10,'Task Breakdown'!$M:$M,$F10) | O10: =N10/8
A11: 10 | B11: Epic 2 | C11: ASWD-2 | D11: Patient Management | E11: 2D | F11: F7 | G11: Set a patient's risk factors and comments | H11: Set risk factors with Yes / No / Unknown -> Assign a predefined comment, or write a patient-specific one | I11: GID-254888, GID-254889 | K11: Medium | L11: Yet to start | M11: M2 | N11: =SUMIFS('Task Breakdown'!$J:$J,'Task Breakdown'!$L:$L,$C11,'Task Breakdown'!$M:$M,$F11) | O11: =N11/8
A12: 11 | B12: Epic 2 | C12: ASWD-2 | D12: Patient Management | E12: 2D | F12: F8 | G12: Manage and translate the risk factor list | H12: Create the `RiskFactors` table -> Create, view, edit and delete risk factors, blocking edit and delete when already used by a patient -> Create `RiskFactorTranslations` -> Enter translated name and description per language | I12: GID-254950, GID-254951, GID-254952, GID-254953, GID-254954 | J12: Yes | K12: Medium | L12: Yet to start | M12: M2 | N12: =SUMIFS('Task Breakdown'!$J:$J,'Task Breakdown'!$L:$L,$C12,'Task Breakdown'!$M:$M,$F12) | O12: =N12/8
A13: 12 | B13: Epic 2 | C13: ASWD-2 | D13: Patient Management | E13: 2D | F13: F9 | G13: Manage and translate the comment list | H13: Create `PredefinedComments` -> Create, view, edit and delete comments, blocking delete when already used -> Create `PredefinedCommentTranslations` -> Enter translated text per language | I13: GID-254955, GID-254956, GID-254957, GID-254958, GID-254959 | J13: Yes | K13: Medium | L13: Yet to start | M13: M2 | N13: =SUMIFS('Task Breakdown'!$J:$J,'Task Breakdown'!$L:$L,$C13,'Task Breakdown'!$M:$M,$F13) | O13: =N13/8
A14: 13 | B14: Epic 5 | C14: ASWD-5 | D14: OAE Test Result | F14: F1 | G14: Investigate the waveform data format and how to draw it | H14: 2-day timeboxed look at the waveform data format and how to draw it | I14: Enabler - no requirement | K14: Medium | L14: Yet to start | M14: M3 | N14: =SUMIFS('Task Breakdown'!$J:$J,'Task Breakdown'!$L:$L,$C14,'Task Breakdown'!$M:$M,$F14) | O14: =N14/8
A15: 14 | B15: Epic 5 | C15: ASWD-5 | D15: OAE Test Result | F15: F2 | G15: Create the OAE result tables and load real device data into them | H15: Create `TEOAEResults` and `DPOAEResults` tables and waveform storage -> Small utility that pushes a real device file through the existing ALGO 5 / AccuLink / ALGO Pro parsers straight into the test tables, so the result views can be demonstrated on genuine screening data before Import is built | I15: Enabler - no requirement | J15: Yes | K15: Medium | L15: Yet to start | M15: M3 | N15: =SUMIFS('Task Breakdown'!$J:$J,'Task Breakdown'!$L:$L,$C15,'Task Breakdown'!$M:$M,$F15) | O15: =N15/8
A16: 15 | B16: Epic 5 | C16: ASWD-5 | D16: OAE Test Result | F16: F3 | G16: Show TEOAE and DPOAE results with waveform, comments and device info | H16: Details, waveform, comments and device info for TEOAE -> Same for DPOAE | I16: GID-254901, GID-254902 | K16: Medium | L16: Yet to start | M16: M3 | N16: =SUMIFS('Task Breakdown'!$J:$J,'Task Breakdown'!$L:$L,$C16,'Task Breakdown'!$M:$M,$F16) | O16: =N16/8
A17: 16 | B17: Epic 6 | C17: ASWD-6 | D17: ABR Test Result | F17: F1 | G17: Create the ABR result table and show results with EEG noise and impedance | H17: Create the `ABRResults` table -> Details, waveform, comments, device info, plus EEG noise and impedance | I17: GID-254903 | J17: Yes | K17: Medium | L17: Yet to start | M17: M3 | N17: =SUMIFS('Task Breakdown'!$J:$J,'Task Breakdown'!$L:$L,$C17,'Task Breakdown'!$M:$M,$F17) | O17: =N17/8
A18: 17 | B18: Epic 7 | C18: ASWD-7 | D18: User Account Management | F18: F1 | G18: Manage user accounts: create, edit, delete, activate, unlock and set language | H18: View the user list -> Create a user -> Edit a user -> Delete a user -> Activate and deactivate -> Unlock an account -> Choose the display language for each user -> Let a user set their own display language from the Settings screen — the dropdown is there but the choice is never stored (carried over from AccuLink) -> Wire this screen's Add/Edit/Delete and Save/Revert/Undo onto Epic 2 F2's shared framework, replacing its own `Stack<UserSnapshot>` copy -> Prevent transfer of deactivated user accounts to the device | I18: GID-254904, GID-254905, GID-254906, GID-254907, GID-254908, GID-254909, GID-254910, GID-255022 | K18: High | L18: Yet to start | M18: M4 | N18: =SUMIFS('Task Breakdown'!$J:$J,'Task Breakdown'!$L:$L,$C18,'Task Breakdown'!$M:$M,$F18) | O18: =N18/8
A19: 18 | B19: Epic 7 | C19: ASWD-7 | D19: User Account Management | F19: F2 | G19: Apply and configure the password and lockout rules everywhere | H19: Move the password rules into `Core` and apply them to every place a password is set, and remove the hardcoded `"1234"` defaults -> Let a signed-in user change their own password from the Settings screen — make Save actually persist, add a current-password check, and stop revealing the password in a plain text box (2.0) -> Let an admin choose None / Simple / Complex, and show what each level actually enforces — the definitions are hardcoded in a resource file today (carried over from AccuLink) -> Screen to set the lockout duration -> Decide what happens to the 90-day expiry — Natus confirmed that it is wanted, so it is built rather than removed; needs a new requirement for the period and the day-91 behaviour -> Prevent reuse of the last three passwords — the rule is coded but can never fire until real accounts exist (F1, defect DF7) | I19: GID-254911, GID-254912, GID-255020 | K19: High | L19: Yet to start | M19: M4 | N19: =SUMIFS('Task Breakdown'!$J:$J,'Task Breakdown'!$L:$L,$C19,'Task Breakdown'!$M:$M,$F19) | O19: =N19/8 | P19: Blocked pending a customer answer, see the plan section 8.
A20: 19 | B20: Epic 8 | C20: ASWD-8 | D20: Profile Management | F20: F1 | G20: Create, view, edit and delete permission profiles | H20: Create the `Profiles` table with its permission fields -> View, create, edit and delete profiles, and show Name / Description / Permissions -> Wire this screen's Add/Edit/Delete and Save/Revert/Undo onto Epic 2 F2's shared framework, replacing any local copy | I20: GID-254913, GID-254914, GID-254915, GID-254916, GID-254917 | J20: Yes | K20: High | L20: Yet to start | M20: M4 | N20: =SUMIFS('Task Breakdown'!$J:$J,'Task Breakdown'!$L:$L,$C20,'Task Breakdown'!$M:$M,$F20) | O20: =N20/8
A21: 20 | B21: Epic 8 | C21: ASWD-8 | D21: Profile Management | F21: F2 | G21: Set permissions per profile and retire the hardcoded roles | H21: Set permissions per profile on the profile screen (2.0) -> Retire the fixed presets in `UserPermissionsViewModel` and read permissions from the database (1.5) | I21: GID-254918 | K21: High | L21: Yet to start | M21: M4 | N21: =SUMIFS('Task Breakdown'!$J:$J,'Task Breakdown'!$L:$L,$C21,'Task Breakdown'!$M:$M,$F21) | O21: =N21/8
A22: 21 | B22: Epic 8 | C22: ASWD-8 | D22: Profile Management | F22: F3 | G22: Complete RBAC: one authorization mechanism, enforced everywhere | H22: Capture the 33 permission fields from `Databases/SettingsDatabase.sql` before that file is deleted, and write them down as the permission model (1.5) -> One authorization service in `Core`: who is signed in, their effective permissions, and a single `Can(permission)` check that everything calls (2.0) -> Enforce in the UI — every command’s `CanExecute`, and a blocked action hidden rather than merely greyed out (2.5) -> Enforce again in the Application layer, so going around a screen does not go around the rule (2.5) -> Re-evaluate a signed-in user’s permissions when their profile changes, without a restart (1.0) -> Every denied action is logged and audited (1.0) -> The permission matrix: 33 permissions × every gated action, written down as both the specification and the test oracle (2.0) -> Tests proving each permission gates its action at both layers, and that patient delete stays available to every user per the 22 Aug decision (2.5) | I22: Enabler - no requirement | J22: Yes | K22: Medium | L22: Yet to start | M22: M4 | N22: =SUMIFS('Task Breakdown'!$J:$J,'Task Breakdown'!$L:$L,$C22,'Task Breakdown'!$M:$M,$F22) | O22: =N22/8
A23: 22 | B23: Epic 9 | C23: ASWD-9 | D23: Device Management | F23: F1 | G23: Create, view, edit and delete screening devices | H23: Create `Devices` and related tables -> View the device list with Name / Serial / Last Seen -> Add, edit and delete a device -> Wire this screen's Add/Edit/Delete and Save/Revert/Undo onto Epic 2 F2's shared framework, replacing any local copy | I23: GID-254919, GID-254920, GID-254921, GID-254922 | J23: Yes | K23: Medium | L23: Yet to start | M23: M4 | N23: =SUMIFS('Task Breakdown'!$J:$J,'Task Breakdown'!$L:$L,$C23,'Task Breakdown'!$M:$M,$F23) | O23: =N23/8
A24: 23 | B24: Epic 9 | C24: ASWD-9 | D24: Device Management | F24: F2 | G24: Assign users and facilities to a device | H24: GID-254923 -> GID-254924 | I24: GID-254923, GID-254924 | K24: Medium | L24: Yet to start | M24: M4 | N24: =SUMIFS('Task Breakdown'!$J:$J,'Task Breakdown'!$L:$L,$C24,'Task Breakdown'!$M:$M,$F24) | O24: =N24/8
A25: 24 | B25: Epic 9 | C25: ASWD-9 | D25: Device Management | F25: F3 | G25: Configure on-device settings and show device system information | H25: Configure the 7 device settings -> Last Seen, Last Updated, Hardware Version, Firmware Version | I25: GID-254925, GID-254926 | K25: Low | L25: Yet to start | M25: M4 | N25: =SUMIFS('Task Breakdown'!$J:$J,'Task Breakdown'!$L:$L,$C25,'Task Breakdown'!$M:$M,$F25) | O25: =N25/8 | P25: Blocked pending a customer answer, see the plan section 8.
A26: 25 | B26: Epic 10 | C26: ASWD-10 | D26: Site Management | F26: F1 | G26: Create, view, edit and delete sites, and set what syncs to devices | H26: Create the `Sites` table -> View, add, edit and delete sites with Name / Description / Code -> Wire this screen's Add/Edit/Delete and Save/Revert/Undo onto Epic 2 F2's shared framework, replacing any local copy -> Setting for whether the site and facility list is pushed to devices during synchronisation — cannot be finished until Epic 21 | I26: GID-254927, GID-254928, GID-254929, GID-254930, GID-254931, GID-255001, GID-255002 | J26: Yes | K26: Medium | L26: Yet to start | M26: M4 | N26: =SUMIFS('Task Breakdown'!$J:$J,'Task Breakdown'!$L:$L,$C26,'Task Breakdown'!$M:$M,$F26) | O26: =N26/8
A27: 26 | B27: Epic 10 | C27: ASWD-10 | D27: Site Management | F27: F2 | G27: Shared “can this record be deleted?” check reused by seven screens | H27: One shared rule set for "can this record be deleted?", reused by Facility, Location, Profile, Device, Protocol, Risk Factor and Comment | I27: Enabler - no requirement | K27: Medium | L27: Yet to start | M27: M4 | N27: =SUMIFS('Task Breakdown'!$J:$J,'Task Breakdown'!$L:$L,$C27,'Task Breakdown'!$M:$M,$F27) | O27: =N27/8
A28: 27 | B28: Epic 11 | C28: ASWD-11 | D28: Facility Management | F28: F1 | G28: Create, view, edit and delete facilities | H28: Create the `Facilities` table -> View, add, edit and delete facilities with Name / Description / Code / Site / Location Type -> Reuse Epic 10's "in use" check -> Wire this screen's Add/Edit/Delete and Save/Revert/Undo onto Epic 2 F2's shared framework, replacing any local copy | I28: GID-254932, GID-254933, GID-254934, GID-254935, GID-254936 | J28: Yes | K28: Medium | L28: Yet to start | M28: M4 | N28: =SUMIFS('Task Breakdown'!$J:$J,'Task Breakdown'!$L:$L,$C28,'Task Breakdown'!$M:$M,$F28) | O28: =N28/8
A29: 28 | B29: Epic 12 | C29: ASWD-12 | D29: Location Management | F29: F1 | G29: Create, view, edit and delete locations, and assign one to every facility | H29: Create the `Locations` table -> View, add, edit and delete locations with Name / Description / Code -> When adding a location, offer to assign it to every facility -> Wire this screen's Add/Edit/Delete and Save/Revert/Undo onto Epic 2 F2's shared framework, replacing any local copy | I29: GID-254937, GID-254938, GID-254939, GID-254940, GID-254941, GID-255465 | J29: Yes | K29: Medium | L29: Yet to start | M29: M4 | N29: =SUMIFS('Task Breakdown'!$J:$J,'Task Breakdown'!$L:$L,$C29,'Task Breakdown'!$M:$M,$F29) | O29: =N29/8
A30: 29 | B30: Epic 13 | C30: ASWD-13 | D30: ABR Test Protocol Configuration | F30: F1 | G30: Create, view, edit and delete ABR test protocols | H30: Create the `ABRProtocols` table with its parameter value ranges -> View, create, edit and delete ABR protocols -> Wire this screen's Add/Edit/Delete and Save/Revert/Undo onto Epic 2 F2's shared framework, replacing any local copy | I30: GID-254942, GID-254943, GID-254944, GID-254945 | J30: Yes | K30: Medium | L30: Yet to start | M30: M4 | N30: =SUMIFS('Task Breakdown'!$J:$J,'Task Breakdown'!$L:$L,$C30,'Task Breakdown'!$M:$M,$F30) | O30: =N30/8
A31: 30 | B31: Epic 14 | C31: ASWD-14 | D31: DPOAE Test Protocol Configuration | F31: F1 | G31: Create, view, edit and delete DPOAE test protocols | H31: Create the `DPOAEProtocols` table with its parameter value ranges -> View, create, edit and delete DPOAE protocols -> Wire this screen's Add/Edit/Delete and Save/Revert/Undo onto Epic 2 F2's shared framework, replacing any local copy | I31: GID-254946, GID-254947, GID-254948, GID-254949 | J31: Yes | K31: Medium | L31: Yet to start | M31: M4 | N31: =SUMIFS('Task Breakdown'!$J:$J,'Task Breakdown'!$L:$L,$C31,'Task Breakdown'!$M:$M,$F31) | O31: =N31/8
A32: 31 | B32: Epic 3 | C32: ASWD-32 | D32: Data Exchange: import, export and S4H | E32: 32A | F32: F1 | G32: Exchange foundation: the record layer, settings, selection and de-identification | H32: Port the record-description and stream layer from AccuLink `Component.Core/Core/DataExchange` — column attributes, and the flat-file, binary and XML readers and writers (3.0) -> Create `ImportConfiguration` and `ExportConfiguration` and save the settings (1.5) -> Choose the export folder, format, and default format (1.5) -> Export new patients / all patients / selected entries / a test date range (2.0) -> Strip demographics and identifiers before export (1.0) -> Connect every parser and writer to the patient repository, so an import is stored and an export reads real data (1.5) | I32: GID-256274, GID-256275, GID-256276, GID-256277, GID-256278, GID-256279, GID-256286, GID-256512 | J32: Yes | K32: High | L32: Yet to start | M32: M5 | N32: =SUMIFS('Task Breakdown'!$J:$J,'Task Breakdown'!$L:$L,$C32,'Task Breakdown'!$M:$M,$F32) | O32: =N32/8
A33: 32 | B33: Epic 3 | C33: ASWD-32 | D33: Data Exchange: import, export and S4H | E33: 32A | F33: F2 | G33: AccuSync XML and JSON — import and export | H33: Agree and write down the AccuSync XML and JSON layout (1.5) -> AccuSync XML and JSON parsers (2.0) -> AccuSync XML and JSON writers with the required file names (2.0) | I33: GID-254900, GID-256280, GID-256281 | K33: High | L33: Yet to start | M33: M5 | N33: =SUMIFS('Task Breakdown'!$J:$J,'Task Breakdown'!$L:$L,$C33,'Task Breakdown'!$M:$M,$F33) | O33: =N33/8
A34: 33 | B34: Epic 3 | C34: ASWD-32 | D34: Data Exchange: import, export and S4H | E34: 32A | F34: F3 | G34: CSV — import and export | H34: CSV writer (2.0) -> Export the on-screen patient list to CSV — Phase 1 per Natus, covered by GID-254898, and it already works today (0.5) -> CSV import matching the writer (1.5) | I34: GID-254898, GID-256284 | K34: Low | L34: Yet to start | M34: M5 | N34: =SUMIFS('Task Breakdown'!$J:$J,'Task Breakdown'!$L:$L,$C34,'Task Breakdown'!$M:$M,$F34) | O34: =N34/8 | P34: Blocked pending a customer answer, see the plan section 8.
A35: 34 | B35: Epic 3 | C35: ASWD-32 | D35: Data Exchange: import, export and S4H | E35: 32A | F35: F4 | G35: ALGO 5 XML and ALGO Pro — import and export | H35: Test harness plus tests for the three existing parsers (2.0) -> Fix the three format defects found in the samples: ALGO Pro duplicate `RiskFactors` keys, the missing ABR/DPOAE marker, and six fields encoded as text in one format and numbers in the other (2.0) -> ALGO 5 XML writer with the required file name (1.5) -> ALGO Pro writer (1.5) | I35: GID-256285 | K35: High | L35: Yet to start | M35: M5 | N35: =SUMIFS('Task Breakdown'!$J:$J,'Task Breakdown'!$L:$L,$C35,'Task Breakdown'!$M:$M,$F35) | O35: =N35/8
A36: 35 | B36: Epic 3 | C36: ASWD-32 | D36: Data Exchange: import, export and S4H | E36: 32A | F36: F5 | G36: AccuLink XML — import and export | H36: AccuLink XML import through the existing parser, with tests (1.5) -> AccuLink XML writer and its typed document, from AccuLink `XmlPatientDataExporter` and the 35 classes generated from `AccuLinkXiMpLe.xsd` (3.0) | I36: Enabler - no requirement | K36: High | L36: Yet to start | M36: M5 | N36: =SUMIFS('Task Breakdown'!$J:$J,'Task Breakdown'!$L:$L,$C36,'Task Breakdown'!$M:$M,$F36) | O36: =N36/8
A37: 36 | B37: Epic 3 | C37: ASWD-32 | D37: Data Exchange: import, export and S4H | E37: 32A | F37: F6 | G37: HiTrack — export, and pick-list import *(fills PM-40’s Nursery and Race lists; Natus supplied sample pick-list files) | H37: HiTrack writer, including the duplicate `INTHS.txt` — the 114-column layout comes from AccuLink `HiTrackTest`, so Q3 no longer blocks it (3.0) -> The export rules that go with it: result codes for deceased and discharged patients, risk-factor and comment aggregation, ethnicity and education code maps (2.0) -> HiTrack pick-list import: hospitals, physicians, audiologists, screeners, nursery types and race types (2.5) | I37: GID-256282 | K37: Medium | L37: Yet to start | M37: M5 | N37: =SUMIFS('Task Breakdown'!$J:$J,'Task Breakdown'!$L:$L,$C37,'Task Breakdown'!$M:$M,$F37) | O37: =N37/8
A38: 37 | B38: Epic 3 | C38: ASWD-32 | D38: Data Exchange: import, export and S4H | E38: 32A | F38: F7 | G38: OZ — binary export | H38: OZ writer — the binary record layout comes from AccuLink `Oz7Test`, so Q3 no longer blocks it (2.5) -> AccuLink has no OZ importer and none is specified. X1 must be answered before any OZ import is planned (0.5) | I38: GID-256283 | K38: Medium | L38: Yet to start | M38: M5 | N38: =SUMIFS('Task Breakdown'!$J:$J,'Task Breakdown'!$L:$L,$C38,'Task Breakdown'!$M:$M,$F38) | O38: =N38/8
A39: 38 | B39: Epic 3 | C39: ASWD-32 | D39: Data Exchange: import, export and S4H | E39: 32B | F39: F8 | G39: S4H: the connector and the sync engine | H39: SOAP client for the SEDQ service — the contract is `northgate.wsdl` with `uploadData` and `downloadSyncData`, so the 3-day discovery is replaced by a read (2.0) -> Client plus a screen to set the web service URL (1.5) -> The shared sync framework and its trigger rules (2.0) -> Send patient and test data to an external system over a web service (1.0) | I39: GID-254899, GID-254974 | K39: High | L39: Yet to start | M39: M7 | N39: =SUMIFS('Task Breakdown'!$J:$J,'Task Breakdown'!$L:$L,$C39,'Task Breakdown'!$M:$M,$F39) | O39: =N39/8 | P39: Blocked pending a customer answer, see the plan section 8.
A40: 39 | B40: Epic 3 | C40: ASWD-32 | D40: Data Exchange: import, export and S4H | E40: 32B | F40: F9 | G40: S4H: receive users, devices, facilities and risk factors | H40: Receive the user list and store username and user ID, read-only (2.0) -> Auto-deactivate and reactivate, default profile and password, block admin adding users (2.5) -> Receive devices from S4H: store device ID, name and serial number, block local edits to them, and follow the service’s active and inactive status (2.0) -> Receive facilities from S4H and keep them in step, read-only locally (2.0) -> Receive risk factors from S4H and keep them in step, read-only locally (2.0) | I40: GID-254975, GID-254977, GID-254978, GID-254979, GID-254980, GID-254981, GID-254982, GID-254983, GID-254984, GID-254985, GID-254986, GID-254987, GID-254988, GID-254989, GID-254990, GID-254991, GID-254992, GID-254993, GID-254994, GID-254995 | K40: High | L40: Yet to start | M40: M7 | N40: =SUMIFS('Task Breakdown'!$J:$J,'Task Breakdown'!$L:$L,$C40,'Task Breakdown'!$M:$M,$F40) | O40: =N40/8
...

Sheet Task Breakdown
A1: Epic | B1: Feature | C1: Title | D1: Sub-Tasks | E1: Development Hours (Design + Implementation + Unit Test) | F1: Testing | G1: W8B8 | H1: Review | I1: Management | J1: Total H | K1: Total Days
F2: 0.1 | G2: 1.2 | H2: 0.1 | I2: 0.05
A3: ASWD-77 | B3: Revamp Code Base | C3: Architecture revamp with MVVM + Clean Architecture | D3: Implementation | E3: 48 | F3: =E3*F$2 | G3: =SUM(E3:F3)*G$2 | H3: =G3*H$2 | I3: =G3*I$2 | J3: =SUM(G3:I3) | K3: =J3/8 | L3: ASWD-77 | M3: F1 | N3: M1
A4: ASWD-1 | B4: F1 - Re-verify login after the branch merge and record traceability | C4: Re-verify the six requirements after the branch merge, record requirement traceability, confirm the 103 tests still pass | D4: Implementation | E4: 40 | F4: =E4*F$2 | G4: =SUM(E4:F4)*G$2 | H4: =G4*H$2 | I4: =G4*I$2 | J4: =SUM(G4:I4) | K4: =J4/8 | L4: ASWD-1 | M4: F1 | N4: M1
D5: Verify against a clean checkout | E5: 7 | F5: =E5*F$2 | G5: =SUM(E5:F5)*G$2 | H5: =G5*H$2 | I5: =G5*I$2 | J5: =SUM(G5:I5) | K5: =J5/8 | L5: ASWD-1 | M5: F1 | N5: M1
A6: ASWD-26 | B6: F1 - Logging that works, and logging in the code already written | C6: Logging interface in Core, file output, four levels (Debug / Info / Warning / Error), the agreed entry format, written to %ProgramData%\Natus\AccuSync\Logs, with exception logging that records type and message but never ex.ToString() (GID-255031, GID-255032, GID-255033, GID-255034, GID-255038) | D6: Writer, levels and the required fields | E6: 6 | F6: =E6*F$2 | G6: =SUM(E6:F6)*G$2 | H6: =G6*H$2 | I6: =G6*I$2 | J6: =SUM(G6:I6) | K6: =J6/8 | L6: ASWD-26 | M6: F1 | N6: M1
D7: Call sites across the affected screens and services | E7: 5 | F7: =E7*F$2 | G7: =SUM(E7:F7)*G$2 | H7: =G7*H$2 | I7: =G7*I$2 | J7: =SUM(G7:I7) | K7: =J7/8 | L7: ASWD-26 | M7: F1 | N7: M1
C8: Convert the existing Debug.WriteLine and Console.WriteLine calls | D8: Convert the existing Debug.WriteLine and Console.WriteLine calls | E8: 5 | F8: =E8*F$2 | G8: =SUM(E8:F8)*G$2 | H8: =G8*H$2 | I8: =G8*I$2 | J8: =SUM(G8:I8) | K8: =J8/8 | L8: ASWD-26 | M8: F1 | N8: M1
C9: Add logging to the Epic 0 and Epic 1 code already written | D9: Call sites across the affected screens and services | E9: 4 | F9: =E9*F$2 | G9: =SUM(E9:F9)*G$2 | H9: =G9*H$2 | I9: =G9*I$2 | J9: =SUM(G9:I9) | K9: =J9/8 | L9: ASWD-26 | M9: F1 | N9: M1
A10: ASWD-2 | B10: F1 - Create, view, edit and delete a patient record | C10: PM-01 - Create the patient tables and repository | D10: Patient entity and EF Core configuration | E10: 8 | F10: =E10*F$2 | G10: =SUM(E10:F10)*G$2 | H10: =G10*H$2 | I10: =G10*I$2 | J10: =SUM(G10:I10) | K10: =J10/8 | L10: ASWD-2 | M10: F1 | N10: M1
D11: Migration and DbContext wiring | E11: 6 | F11: =E11*F$2 | G11: =SUM(E11:F11)*G$2 | H11: =G11*H$2 | I11: =G11*I$2 | J11: =SUM(G11:I11) | K11: =J11/8 | L11: ASWD-2 | M11: F1 | N11: M1
D12: Repository and service methods | E12: 4 | F12: =E12*F$2 | G12: =SUM(E12:F12)*G$2 | H12: =G12*H$2 | I12: =G12*I$2 | J12: =SUM(G12:I12) | K12: =J12/8 | L12: ASWD-2 | M12: F1 | N12: M1
C13: PM-03 - Add a new patient | D13: Core model and service | E13: 6 | F13: =E13*F$2 | G13: =SUM(E13:F13)*G$2 | H13: =G13*H$2 | I13: =G13*I$2 | J13: =SUM(G13:I13) | K13: =J13/8 | L13: ASWD-2 | M13: F1 | N13: M1
D14: ViewModel, DTO and converters | E14: 6 | F14: =E14*F$2 | G14: =SUM(E14:F14)*G$2 | H14: =G14*H$2 | I14: =G14*I$2 | J14: =SUM(G14:I14) | K14: =J14/8 | L14: ASWD-2 | M14: F1 | N14: M1
D15: Screen (XAML) and command wiring | E15: 4 | F15: =E15*F$2 | G15: =SUM(E15:F15)*G$2 | H15: =G15*H$2 | I15: =G15*I$2 | J15: =SUM(G15:I15) | K15: =J15/8 | L15: ASWD-2 | M15: F1 | N15: M1
C16: PM-04 - View and edit a patient, and fix the two data bugs | D16: Core model and service | E16: 4 | F16: =E16*F$2 | G16: =SUM(E16:F16)*G$2 | H16: =G16*H$2 | I16: =G16*I$2 | J16: =SUM(G16:I16) | K16: =J16/8 | L16: ASWD-2 | M16: F1 | N16: M1
D17: ViewModel, DTO and converters | E17: 2 | F17: =E17*F$2 | G17: =SUM(E17:F17)*G$2 | H17: =G17*H$2 | I17: =G17*I$2 | J17: =SUM(G17:I17) | K17: =J17/8 | L17: ASWD-2 | M17: F1 | N17: M1
D18: Screen (XAML) and command wiring | E18: 2 | F18: =E18*F$2 | G18: =SUM(E18:F18)*G$2 | H18: =G18*H$2 | I18: =G18*I$2 | J18: =SUM(G18:I18) | K18: =J18/8 | L18: ASWD-2 | M18: F1 | N18: M1
C19: PM-05 - Delete a patient (soft delete) | D19: Core model and service | E19: 3 | F19: =E19*F$2 | G19: =SUM(E19:F19)*G$2 | H19: =G19*H$2 | I19: =G19*I$2 | J19: =SUM(G19:I19) | K19: =J19/8 | L19: ASWD-2 | M19: F1 | N19: M1
D20: ViewModel, DTO and converters | E20: 2 | F20: =E20*F$2 | G20: =SUM(E20:F20)*G$2 | H20: =G20*H$2 | I20: =G20*I$2 | J20: =SUM(G20:I20) | K20: =J20/8 | L20: ASWD-2 | M20: F1 | N20: M1
D21: Screen (XAML) and command wiring | E21: 2 | F21: =E21*F$2 | G21: =SUM(E21:F21)*G$2 | H21: =G21*H$2 | I21: =G21*I$2 | J21: =SUM(G21:I21) | K21: =J21/8 | L21: ASWD-2 | M21: F1 | N21: M1
C22: PM-06 - Save the patient's contact details | D22: Core model and service | E22: 3 | F22: =E22*F$2 | G22: =SUM(E22:F22)*G$2 | H22: =G22*H$2 | I22: =G22*I$2 | J22: =SUM(G22:I22) | K22: =J22/8 | L22: ASWD-2 | M22: F1 | N22: M1
D23: ViewModel, DTO and converters | E23: 2 | F23: =E23*F$2 | G23: =SUM(E23:F23)*G$2 | H23: =G23*H$2 | I23: =G23*I$2 | J23: =SUM(G23:I23) | K23: =J23/8 | L23: ASWD-2 | M23: F1 | N23: M1
D24: Screen (XAML) and command wiring | E24: 2 | F24: =E24*F$2 | G24: =SUM(E24:F24)*G$2 | H24: =G24*H$2 | I24: =G24*I$2 | J24: =SUM(G24:I24) | K24: =J24/8 | L24: ASWD-2 | M24: F1 | N24: M1
C25: PM-40 - Add the AccuLink fields AccuSync is missing | D25: Core model and service | E25: 10 | F25: =E25*F$2 | G25: =SUM(E25:F25)*G$2 | H25: =G25*H$2 | I25: =G25*I$2 | J25: =SUM(G25:I25) | K25: =J25/8 | L25: ASWD-2 | M25: F1 | N25: M1
D26: ViewModel, DTO and converters | E26: 8 | F26: =E26*F$2 | G26: =SUM(E26:F26)*G$2 | H26: =G26*H$2 | I26: =G26*I$2 | J26: =SUM(G26:I26) | K26: =J26/8 | L26: ASWD-2 | M26: F1 | N26: M1
D27: Screen (XAML) and command wiring | E27: 12 | F27: =E27*F$2 | G27: =SUM(E27:F27)*G$2 | H27: =G27*H$2 | I27: =G27*I$2 | J27: =SUM(G27:I27) | K27: =J27/8 | L27: ASWD-2 | M27: F1 | N27: M1
C28: PM-39 - Add the ALGO device fields | D28: Core model and service | E28: 10 | F28: =E28*F$2 | G28: =SUM(E28:F28)*G$2 | H28: =G28*H$2 | I28: =G28*I$2 | J28: =SUM(G28:I28) | K28: =J28/8 | L28: ASWD-2 | M28: F1 | N28: M1
D29: ViewModel, DTO and converters | E29: 8 | F29: =E29*F$2 | G29: =SUM(E29:F29)*G$2 | H29: =G29*H$2 | I29: =G29*I$2 | J29: =SUM(G29:I29) | K29: =J29/8 | L29: ASWD-2 | M29: F1 | N29: M1
D30: Screen (XAML) and command wiring | E30: 12 | F30: =E30*F$2 | G30: =SUM(E30:F30)*G$2 | H30: =G30*H$2 | I30: =G30*I$2 | J30: =SUM(G30:I30) | K30: =J30/8 | L30: ASWD-2 | M30: F1 | N30: M1
B31: F2 - Shared Add/Edit/Delete and Save/Revert/Undo framework | C31: PM-07 - Build the shared Add, Edit and Delete buttons | D31: Implementation | E31: 8 | F31: =E31*F$2 | G31: =SUM(E31:F31)*G$2 | H31: =G31*H$2 | I31: =G31*I$2 | J31: =SUM(G31:I31) | K31: =J31/8 | L31: ASWD-2 | M31: F2 | N31: M1
D32: Verify against a clean checkout | E32: 6 | F32: =E32*F$2 | G32: =SUM(E32:F32)*G$2 | H32: =G32*H$2 | I32: =G32*I$2 | J32: =SUM(G32:I32) | K32: =J32/8 | L32: ASWD-2 | M32: F2 | N32: M1
C33: PM-08 - Build the shared Save, Revert and Undo | D33: Implementation | E33: 8 | F33: =E33*F$2 | G33: =SUM(E33:F33)*G$2 | H33: =G33*H$2 | I33: =G33*I$2 | J33: =SUM(G33:I33) | K33: =J33/8 | L33: ASWD-2 | M33: F2 | N33: M1
D34: Verify against a clean checkout | E34: 6 | F34: =E34*F$2 | G34: =SUM(E34:F34)*G$2 | H34: =G34*H$2 | I34: =G34*I$2 | J34: =SUM(G34:I34) | K34: =J34/8 | L34: ASWD-2 | M34: F2 | N34: M1
C35: PM-09 - Warn before losing unsaved changes | D35: Core model and service | E35: 6 | F35: =E35*F$2 | G35: =SUM(E35:F35)*G$2 | H35: =G35*H$2 | I35: =G35*I$2 | J35: =SUM(G35:I35) | K35: =J35/8 | L35: ASWD-2 | M35: F2 | N35: M1
D36: ViewModel, DTO and converters | E36: 5 | F36: =E36*F$2 | G36: =SUM(E36:F36)*G$2 | H36: =G36*H$2 | I36: =G36*I$2 | J36: =SUM(G36:I36) | K36: =J36/8 | L36: ASWD-2 | M36: F2 | N36: M1
D37: Screen (XAML) and command wiring | E37: 7 | F37: =E37*F$2 | G37: =SUM(E37:F37)*G$2 | H37: =G37*H$2 | I37: =G37*I$2 | J37: =SUM(G37:I37) | K37: =J37/8 | L37: ASWD-2 | M37: F2 | N37: M1
B38: F3 - Show and search the patient list | C38: PM-10 - Show the patient list | D38: Core model and service | E38: 2 | F38: =E38*F$2 | G38: =SUM(E38:F38)*G$2 | H38: =G38*H$2 | I38: =G38*I$2 | J38: =SUM(G38:I38) | K38: =J38/8 | L38: ASWD-2 | M38: F3 | N38: M1
D39: ViewModel, DTO and converters | E39: 2 | F39: =E39*F$2 | G39: =SUM(E39:F39)*G$2 | H39: =G39*H$2 | I39: =G39*I$2 | J39: =SUM(G39:I39) | K39: =J39/8 | L39: ASWD-2 | M39: F3 | N39: M1
D40: Screen (XAML) and command wiring | E40: 4 | F40: =E40*F$2 | G40: =SUM(E40:F40)*G$2 | H40: =G40*H$2 | I40: =G40*I$2 | J40: =SUM(G40:I40) | K40: =J40/8 | L40: ASWD-2 | M40: F3 | N40: M1
...
